<robot name="threeLinkHuman_subject9">
    <link name="foot">
        <inertial>
            <mass value="5.0758"/>
            <origin xyz="0 0 0.028365" rpy="0 0 0" />
            <inertia ixx="0.033933" iyy="0.024702" izz="0.055912" ixy="0" ixz="0" iyz="0"/>
        </inertial>

        <visual>
			<origin xyz="0 0 0.028365" rpy="0 0 0" />
            <geometry>
                <box size="0.23491 0.2775 0.05673"/>
            </geometry>
        </visual>

        <collision>
			<origin xyz="0 0 0.028365" rpy="0 0 0" />
            <geometry>
                <box size="0.23491 0.2775 0.05673"/>
            </geometry>
        </collision>
    </link>
    
    <link name="leg">
        <inertial>
            <mass value="35.6055"/>
            <origin xyz="0 0 0.42351" rpy="0 0 0" />
            <inertia ixx="2.3305" iyy="2.1696" izz="0.24267" ixy="0" ixz="0" iyz="0"/>
        </inertial>

        <visual>
            <origin xyz="0 0 0.42351" rpy="0 0 0" />
            <geometry>
                <box size="0.11745 0.26075 0.84702"/>
            </geometry>
        </visual>

        <collision>
            <origin xyz="0 0 0.42351" rpy="0 0 0" />
            <geometry>
                <box size="0.11745 0.26075 0.84702"/>
            </geometry>
        </collision>
    </link>
    
    <link name="torso">
        <inertial>
            <mass value="28.3345"/>
            <origin xyz="0 0 0.24796" rpy="0 0 0" />
            <inertia ixx="0.87728" iyy="0.61327" izz="0.32916" ixy="0" ixz="0" iyz="0"/>
        </inertial>

        <visual>
            <origin xyz="0 0 0.24796" rpy="0 0 0" />
            <geometry>
                <box size="0.11745 0.35441 0.49591"/>
            </geometry>
        </visual>

        <collision>
            <origin xyz="0 0 0.24796" rpy="0 0 0" />
            <geometry>
                <box size="0.11745 0.35441 0.49591"/>
            </geometry>
        </collision>
    </link>
        
    <joint name="ankle" type="revolute">
        <origin xyz="-0.058726 0 0.05673" rpy="0 0 0"/>
        <parent link="foot"/>
        <child link="leg"/>
        <dynamics damping="0.1" friction="0.0"/>
        <limit effort="30" velocity="1.0" lower="-10.0" upper="10.0" />
        <axis xyz="0 1 0" />
    </joint>
    
    <joint name="hip" type="revolute">
        <origin xyz="0 0 0.84702" rpy="0 0 0"/>
        <parent link="leg"/>
        <child link="torso"/>
        <dynamics damping="0.1" friction="0.0"/>
        <limit effort="30" velocity="1.0" lower="-10.0" upper="10.0" />
        <axis xyz="0 1 0" />
    </joint>

</robot>
