<robot name="threeLinkHuman">
    <link name="foot">
        <inertial>
            <mass value="5.2252"/>
            <origin xyz="0 0 0.028367" rpy="0 0 0" />
            <inertia ixx="0.035016" iyy="0.025449" izz="0.057662" ixy="0" ixz="0" iyz="0"/>
        </inertial>

        <visual>
			<origin xyz="0 0 0.028367" rpy="0 0 0" />
            <geometry>
                <box size="0.235 0.27785 0.056733"/>
            </geometry>
        </visual>

        <collision>
			<origin xyz="0 0 0.028367" rpy="0 0 0" />
            <geometry>
                <box size="0.235 0.27785 0.056733"/>
            </geometry>
        </collision>
    </link>
    
    <link name="leg">
        <inertial>
            <mass value="34.7124"/>
            <origin xyz="0 0 0.42234" rpy="0 0 0" />
            <inertia ixx="2.2418" iyy="2.1039" izz="0.21777" ixy="0" ixz="0" iyz="0"/>
        </inertial>

        <visual>
            <origin xyz="0 0 0.42234" rpy="0 0 0" />
            <geometry>
                <box size="0.1175 0.24795 0.84469"/>
            </geometry>
        </visual>

        <collision>
            <origin xyz="0 0 0.42234" rpy="0 0 0" />
            <geometry>
                <box size="0.1175 0.24795 0.84469"/>
            </geometry>
        </collision>
    </link>
    
    <link name="torso">
        <inertial>
            <mass value="28.9538"/>
            <origin xyz="0 0 0.24685" rpy="0 0 0" />
            <inertia ixx="0.8902" iyy="0.62141" izz="0.33541" ixy="0" ixz="0" iyz="0"/>
        </inertial>

        <visual>
            <origin xyz="0 0 0.24685" rpy="0 0 0" />
            <geometry>
                <box size="0.1175 0.35384 0.4937"/>
            </geometry>
        </visual>

        <collision>
            <origin xyz="0 0 0.24685" rpy="0 0 0" />
            <geometry>
                <box size="0.1175 0.35384 0.4937"/>
            </geometry>
        </collision>
    </link>
        
    <joint name="ankle" type="revolute">
        <origin xyz="-0.058751 0 0.056733" rpy="0 0 0"/>
        <parent link="foot"/>
        <child link="leg"/>
        <dynamics damping="0.1" friction="0.0"/>
        <limit effort="30" velocity="1.0" lower="-10.0" upper="10.0" />
        <axis xyz="0 1 0" />
    </joint>
    
    <joint name="hip" type="revolute">
        <origin xyz="0 0 0.84469" rpy="0 0 0"/>
        <parent link="leg"/>
        <child link="torso"/>
        <dynamics damping="0.1" friction="0.0"/>
        <limit effort="30" velocity="1.0" lower="-10.0" upper="10.0" />
        <axis xyz="0 1 0" />
    </joint>

</robot>
