<robot name="threeLinkHuman">
    <link name="foot">
        <inertial>
            <mass value="4.8738"/>
            <origin xyz="0 0 0.030802" rpy="0 0 0" />
            <inertia ixx="0.023979" iyy="0.024665" izz="0.045561" ixy="0" ixz="0" iyz="0"/>
        </inertial>

        <visual>
			<origin xyz="0 0 0.030802" rpy="0 0 0" />
            <geometry>
                <box size="0.23861 0.23504 0.061603"/>
            </geometry>
        </visual>

        <collision>
			<origin xyz="0 0 0.030802" rpy="0 0 0" />
            <geometry>
                <box size="0.23861 0.23504 0.061603"/>
            </geometry>
        </collision>
    </link>
    
    <link name="leg">
        <inertial>
            <mass value="36.3607"/>
            <origin xyz="0 0 0.41309" rpy="0 0 0" />
            <inertia ixx="2.2754" iyy="2.1113" izz="0.25034" ixy="0" ixz="0" iyz="0"/>
        </inertial>

        <visual>
            <origin xyz="0 0 0.41309" rpy="0 0 0" />
            <geometry>
                <box size="0.1193 0.2615 0.82618"/>
            </geometry>
        </visual>

        <collision>
            <origin xyz="0 0 0.41309" rpy="0 0 0" />
            <geometry>
                <box size="0.1193 0.2615 0.82618"/>
            </geometry>
        </collision>
    </link>
    
    <link name="torso">
        <inertial>
            <mass value="29.345"/>
            <origin xyz="0 0 0.24618" rpy="0 0 0" />
            <inertia ixx="0.8995" iyy="0.62762" izz="0.34149" ixy="0" ixz="0" iyz="0"/>
        </inertial>

        <visual>
            <origin xyz="0 0 0.24618" rpy="0 0 0" />
            <geometry>
                <box size="0.1193 0.35413 0.49236"/>
            </geometry>
        </visual>

        <collision>
            <origin xyz="0 0 0.24618" rpy="0 0 0" />
            <geometry>
                <box size="0.1193 0.35413 0.49236"/>
            </geometry>
        </collision>
    </link>
        
    <joint name="ankle" type="revolute">
        <origin xyz="-0.059652 0 0.061603" rpy="0 0 0"/>
        <parent link="foot"/>
        <child link="leg"/>
        <dynamics damping="0.1" friction="0.0"/>
        <limit effort="30" velocity="1.0" lower="-10.0" upper="10.0" />
        <axis xyz="0 1 0" />
    </joint>
    
    <joint name="hip" type="revolute">
        <origin xyz="0 0 0.82618" rpy="0 0 0"/>
        <parent link="leg"/>
        <child link="torso"/>
        <dynamics damping="0.1" friction="0.0"/>
        <limit effort="30" velocity="1.0" lower="-10.0" upper="10.0" />
        <axis xyz="0 1 0" />
    </joint>

</robot>
