<robot name="threeLinkHuman_subject10">
    <link name="foot">
        <inertial>
            <mass value="4.8692"/>
            <origin xyz="0 0 0.030902" rpy="0 0 0" />
            <inertia ixx="0.024317" iyy="0.024396" izz="0.045612" ixy="0" ixz="0" iyz="0"/>
        </inertial>

        <visual>
			<origin xyz="0 0 0.030902" rpy="0 0 0" />
            <geometry>
                <box size="0.23728 0.23687 0.061803"/>
            </geometry>
        </visual>

        <collision>
			<origin xyz="0 0 0.030902" rpy="0 0 0" />
            <geometry>
                <box size="0.23728 0.23687 0.061803"/>
            </geometry>
        </collision>
    </link>
    
    <link name="leg">
        <inertial>
            <mass value="36.8554"/>
            <origin xyz="0 0 0.41348" rpy="0 0 0" />
            <inertia ixx="2.3209" iyy="2.1436" izz="0.2638" ixy="0" ixz="0" iyz="0"/>
        </inertial>

        <visual>
            <origin xyz="0 0 0.41348" rpy="0 0 0" />
            <geometry>
                <box size="0.11864 0.26798 0.82696"/>
            </geometry>
        </visual>

        <collision>
            <origin xyz="0 0 0.41348" rpy="0 0 0" />
            <geometry>
                <box size="0.11864 0.26798 0.82696"/>
            </geometry>
        </collision>
    </link>
    
    <link name="torso">
        <inertial>
            <mass value="29.0139"/>
            <origin xyz="0 0 0.24646" rpy="0 0 0" />
            <inertia ixx="0.89034" iyy="0.6215" izz="0.33691" ixy="0" ixz="0" iyz="0"/>
        </inertial>

        <visual>
            <origin xyz="0 0 0.24646" rpy="0 0 0" />
            <geometry>
                <box size="0.11864 0.35393 0.49292"/>
            </geometry>
        </visual>

        <collision>
            <origin xyz="0 0 0.24646" rpy="0 0 0" />
            <geometry>
                <box size="0.11864 0.35393 0.49292"/>
            </geometry>
        </collision>
    </link>
        
    <joint name="ankle" type="revolute">
        <origin xyz="-0.05932 0 0.061803" rpy="0 0 0"/>
        <parent link="foot"/>
        <child link="leg"/>
        <dynamics damping="0.1" friction="0.0"/>
        <limit effort="30" velocity="1.0" lower="-10.0" upper="10.0" />
        <axis xyz="0 1 0" />
    </joint>
    
    <joint name="hip" type="revolute">
        <origin xyz="0 0 0.82696" rpy="0 0 0"/>
        <parent link="leg"/>
        <child link="torso"/>
        <dynamics damping="0.1" friction="0.0"/>
        <limit effort="30" velocity="1.0" lower="-10.0" upper="10.0" />
        <axis xyz="0 1 0" />
    </joint>

</robot>
