<robot name="threeLinkHuman">
    <link name="foot">
        <inertial>
            <mass value="4.8865"/>
            <origin xyz="0 0 0.031004" rpy="0 0 0" />
            <inertia ixx="0.024518" iyy="0.02451" izz="0.045897" ixy="0" ixz="0" iyz="0"/>
        </inertial>

        <visual>
			<origin xyz="0 0 0.031004" rpy="0 0 0" />
            <geometry>
                <box size="0.23737 0.23741 0.062009"/>
            </geometry>
        </visual>

        <collision>
			<origin xyz="0 0 0.031004" rpy="0 0 0" />
            <geometry>
                <box size="0.23737 0.23741 0.062009"/>
            </geometry>
        </collision>
    </link>
    
    <link name="leg">
        <inertial>
            <mass value="36.8533"/>
            <origin xyz="0 0 0.41319" rpy="0 0 0" />
            <inertia ixx="2.319" iyy="2.1405" izz="0.26501" ixy="0" ixz="0" iyz="0"/>
        </inertial>

        <visual>
            <origin xyz="0 0 0.41319" rpy="0 0 0" />
            <geometry>
                <box size="0.11869 0.26871 0.82637"/>
            </geometry>
        </visual>

        <collision>
            <origin xyz="0 0 0.41319" rpy="0 0 0" />
            <geometry>
                <box size="0.11869 0.26871 0.82637"/>
            </geometry>
        </collision>
    </link>
    
    <link name="torso">
        <inertial>
            <mass value="28.9449"/>
            <origin xyz="0 0 0.24644" rpy="0 0 0" />
            <inertia ixx="0.88797" iyy="0.61992" izz="0.336" ixy="0" ixz="0" iyz="0"/>
        </inertial>

        <visual>
            <origin xyz="0 0 0.24644" rpy="0 0 0" />
            <geometry>
                <box size="0.11869 0.35385 0.49287"/>
            </geometry>
        </visual>

        <collision>
            <origin xyz="0 0 0.24644" rpy="0 0 0" />
            <geometry>
                <box size="0.11869 0.35385 0.49287"/>
            </geometry>
        </collision>
    </link>
        
    <joint name="ankle" type="revolute">
        <origin xyz="-0.059343 0 0.062009" rpy="0 0 0"/>
        <parent link="foot"/>
        <child link="leg"/>
        <dynamics damping="0.1" friction="0.0"/>
        <limit effort="30" velocity="1.0" lower="-10.0" upper="10.0" />
        <axis xyz="0 1 0" />
    </joint>
    
    <joint name="hip" type="revolute">
        <origin xyz="0 0 0.82637" rpy="0 0 0"/>
        <parent link="leg"/>
        <child link="torso"/>
        <dynamics damping="0.1" friction="0.0"/>
        <limit effort="30" velocity="1.0" lower="-10.0" upper="10.0" />
        <axis xyz="0 1 0" />
    </joint>

</robot>
