<robot name="threeLinkHuman">
    <link name="foot">
        <inertial>
            <mass value="4.3179"/>
            <origin xyz="0 0 0.030719" rpy="0 0 0" />
            <inertia ixx="0.018205" iyy="0.019139" izz="0.034627" ixy="0" ixz="0" iyz="0"/>
        </inertial>

        <visual>
			<origin xyz="0 0 0.030719" rpy="0 0 0" />
            <geometry>
                <box size="0.22229 0.21638 0.061439"/>
            </geometry>
        </visual>

        <collision>
			<origin xyz="0 0 0.030719" rpy="0 0 0" />
            <geometry>
                <box size="0.22229 0.21638 0.061439"/>
            </geometry>
        </collision>
    </link>
    
    <link name="leg">
        <inertial>
            <mass value="30.6242"/>
            <origin xyz="0 0 0.40208" rpy="0 0 0" />
            <inertia ixx="1.7907" iyy="1.6819" izz="0.17185" ixy="0" ixz="0" iyz="0"/>
        </inertial>

        <visual>
            <origin xyz="0 0 0.40208" rpy="0 0 0" />
            <geometry>
                <box size="0.11115 0.23449 0.80417"/>
            </geometry>
        </visual>

        <collision>
            <origin xyz="0 0 0.40208" rpy="0 0 0" />
            <geometry>
                <box size="0.11115 0.23449 0.80417"/>
            </geometry>
        </collision>
    </link>
    
    <link name="torso">
        <inertial>
            <mass value="33.6115"/>
            <origin xyz="0 0 0.2457" rpy="0 0 0" />
            <inertia ixx="0.88222" iyy="0.60522" izz="0.33591" ixy="0" ixz="0" iyz="0"/>
        </inertial>

        <visual>
            <origin xyz="0 0 0.2457" rpy="0 0 0" />
            <geometry>
                <box size="0.11115 0.35851 0.49141"/>
            </geometry>
        </visual>

        <collision>
            <origin xyz="0 0 0.2457" rpy="0 0 0" />
            <geometry>
                <box size="0.11115 0.35851 0.49141"/>
            </geometry>
        </collision>
    </link>
        
    <joint name="ankle" type="revolute">
        <origin xyz="-0.055573 0 0.061439" rpy="0 0 0"/>
        <parent link="foot"/>
        <child link="leg"/>
        <dynamics damping="0.1" friction="0.0"/>
        <limit effort="30" velocity="1.0" lower="-10.0" upper="10.0" />
        <axis xyz="0 1 0" />
    </joint>
    
    <joint name="hip" type="revolute">
        <origin xyz="0 0 0.80417" rpy="0 0 0"/>
        <parent link="leg"/>
        <child link="torso"/>
        <dynamics damping="0.1" friction="0.0"/>
        <limit effort="30" velocity="1.0" lower="-10.0" upper="10.0" />
        <axis xyz="0 1 0" />
    </joint>

</robot>
