<robot name="threeLinkHuman">
    <link name="foot">
        <inertial>
            <mass value="4.7562"/>
            <origin xyz="0 0 0.031065" rpy="0 0 0" />
            <inertia ixx="0.021675" iyy="0.021183" izz="0.039798" ixy="0" ixz="0" iyz="0"/>
        </inertial>

        <visual>
			<origin xyz="0 0 0.031065" rpy="0 0 0" />
            <geometry>
                <box size="0.22268 0.22544 0.062131"/>
            </geometry>
        </visual>

        <collision>
			<origin xyz="0 0 0.031065" rpy="0 0 0" />
            <geometry>
                <box size="0.22268 0.22544 0.062131"/>
            </geometry>
        </collision>
    </link>
    
    <link name="leg">
        <inertial>
            <mass value="34.1076"/>
            <origin xyz="0 0 0.40218" rpy="0 0 0" />
            <inertia ixx="2.0163" iyy="1.8742" izz="0.21253" ixy="0" ixz="0" iyz="0"/>
        </inertial>

        <visual>
            <origin xyz="0 0 0.40218" rpy="0 0 0" />
            <geometry>
                <box size="0.11134 0.24976 0.80437"/>
            </geometry>
        </visual>

        <collision>
            <origin xyz="0 0 0.40218" rpy="0 0 0" />
            <geometry>
                <box size="0.11134 0.24976 0.80437"/>
            </geometry>
        </collision>
    </link>
    
    <link name="torso">
        <inertial>
            <mass value="29.6627"/>
            <origin xyz="0 0 0.24219" rpy="0 0 0" />
            <inertia ixx="0.90156" iyy="0.61059" izz="0.35225" ixy="0" ixz="0" iyz="0"/>
        </inertial>

        <visual>
            <origin xyz="0 0 0.24219" rpy="0 0 0" />
            <geometry>
                <box size="0.11134 0.3607 0.48437"/>
            </geometry>
        </visual>

        <collision>
            <origin xyz="0 0 0.24219" rpy="0 0 0" />
            <geometry>
                <box size="0.11134 0.3607 0.48437"/>
            </geometry>
        </collision>
    </link>
        
    <joint name="ankle" type="revolute">
        <origin xyz="-0.055669 0 0.062131" rpy="0 0 0"/>
        <parent link="foot"/>
        <child link="leg"/>
        <dynamics damping="0.1" friction="0.0"/>
        <limit effort="30" velocity="1.0" lower="-10.0" upper="10.0" />
        <axis xyz="0 1 0" />
    </joint>
    
    <joint name="hip" type="revolute">
        <origin xyz="0 0 0.80437" rpy="0 0 0"/>
        <parent link="leg"/>
        <child link="torso"/>
        <dynamics damping="0.1" friction="0.0"/>
        <limit effort="30" velocity="1.0" lower="-10.0" upper="10.0" />
        <axis xyz="0 1 0" />
    </joint>

</robot>
