<robot name="threeLinkHuman">
    <link name="foot">
        <inertial>
            <mass value="4.0406"/>
            <origin xyz="0 0 0.030582" rpy="0 0 0" />
            <inertia ixx="0.016863" iyy="0.0186" izz="0.032944" ixy="0" ixz="0" iyz="0"/>
        </inertial>

        <visual>
			<origin xyz="0 0 0.030582" rpy="0 0 0" />
            <geometry>
                <box size="0.22693 0.21527 0.061164"/>
            </geometry>
        </visual>

        <collision>
			<origin xyz="0 0 0.030582" rpy="0 0 0" />
            <geometry>
                <box size="0.22693 0.21527 0.061164"/>
            </geometry>
        </collision>
    </link>
    
    <link name="leg">
        <inertial>
            <mass value="32.831"/>
            <origin xyz="0 0 0.44687" rpy="0 0 0" />
            <inertia ixx="2.3422" iyy="2.2206" izz="0.19203" ixy="0" ixz="0" iyz="0"/>
        </inertial>

        <visual>
            <origin xyz="0 0 0.44687" rpy="0 0 0" />
            <geometry>
                <box size="0.11347 0.2394 0.89374"/>
            </geometry>
        </visual>

        <collision>
            <origin xyz="0 0 0.44687" rpy="0 0 0" />
            <geometry>
                <box size="0.11347 0.2394 0.89374"/>
            </geometry>
        </collision>
    </link>
    
    <link name="torso">
        <inertial>
            <mass value="20.0619"/>
            <origin xyz="0 0 0.21934" rpy="0 0 0" />
            <inertia ixx="0.47023" iyy="0.34324" izz="0.17004" ixy="0" ixz="0" iyz="0"/>
        </inertial>

        <visual>
            <origin xyz="0 0 0.21934" rpy="0 0 0" />
            <geometry>
                <box size="0.11347 0.29805 0.43867"/>
            </geometry>
        </visual>

        <collision>
            <origin xyz="0 0 0.21934" rpy="0 0 0" />
            <geometry>
                <box size="0.11347 0.29805 0.43867"/>
            </geometry>
        </collision>
    </link>
        
    <joint name="ankle" type="revolute">
        <origin xyz="-0.056733 0 0.061164" rpy="0 0 0"/>
        <parent link="foot"/>
        <child link="leg"/>
        <dynamics damping="0.1" friction="0.0"/>
        <limit effort="30" velocity="1.0" lower="-10.0" upper="10.0" />
        <axis xyz="0 1 0" />
    </joint>
    
    <joint name="hip" type="revolute">
        <origin xyz="0 0 0.89374" rpy="0 0 0"/>
        <parent link="leg"/>
        <child link="torso"/>
        <dynamics damping="0.1" friction="0.0"/>
        <limit effort="30" velocity="1.0" lower="-10.0" upper="10.0" />
        <axis xyz="0 1 0" />
    </joint>

</robot>
