<robot name="threeLinkHuman_subject1">
    <link name="foot">
        <inertial>
            <mass value="2.191"/>
            <origin xyz="0 0 0" rpy="0 0 0" />
            <inertia ixx="0.004" iyy="0.011" izz="0.013" ixy="0" ixz="0" iyz="0"/>
        </inertial>

        <visual>
            <geometry>
                <box size="0.128 0.072 0.229"/>
            </geometry>
        </visual>

        <collision>
            <geometry>
                <box size="0.128 0.072 0.229"/>
            </geometry>
        </collision>
    </link>
    
    <link name="leg">
        <inertial>
            <mass value="26.287"/>
            <origin xyz="0 0 0.072" rpy="0 0 0" />
            <inertia ixx="1.798" iyy="1.684" izz="0.171" ixy="0" ixz="0" iyz="0"/>
        </inertial>

        <visual>
            <origin xyz="0 0 0.072" rpy="0 0 0" />
            <geometry>
                <box size="0.255 0.869 0.114"/>
            </geometry>
        </visual>

        <collision>
            <origin xyz="0 0 0.072" rpy="0 0 0" />
            <geometry>
                <box size="0.255 0.869 0.114"/>
            </geometry>
        </collision>
    </link>
    
    <link name="torso">
        <inertial>
            <mass value="18.059"/>
            <origin xyz="0 0 0.869" rpy="0 0 0" />
            <inertia ixx="0.490" iyy="0.352" izz="0.177" ixy="0" ixz="0" iyz="0"/>
        </inertial>

        <visual>
            <origin xyz="0 0 0.869" rpy="0 0 0" />
            <geometry>
                <box size="0.324 0.470 0.114"/>
            </geometry>
        </visual>

        <collision>
            <origin xyz="0 0 0.869" rpy="0 0 0" />
            <geometry>
                <box size="0.324 0.470 0.114"/>
            </geometry>
        </collision>
    </link>
        
    <joint name="ankle" type="revolute">
        <origin xyz="-0.0575 0.0 0.036" rpy="0 0 0"/>
        <parent link="foot"/>
        <child link="leg"/>
        <dynamics damping="0.1" friction="0.0"/>
        <limit effort="30" velocity="1.0" lower="-10.0" upper="10.0" />
        <axis xyz="0 1 0" />
    </joint>
    
    <joint name="hip" type="revolute">
        <origin xyz="0.0 0.0 0.869" rpy="0 0 0"/>
        <parent link="leg"/>
        <child link="torso"/>
        <dynamics damping="0.1" friction="0.0"/>
        <limit effort="30" velocity="1.0" lower="-10.0" upper="10.0" />
        <axis xyz="0 1 0" />
    </joint>

</robot>
