<robot name="threeLinkHuman">
    <link name="foot">
        <inertial>
            <mass value="1"/>
            <origin xyz="0 0 0" rpy="0 0 0" />
            <inertia ixx="0.0017" iyy="0.0017" izz="0.0017" ixy="0" ixz="0" iyz="0"/>
        </inertial>

        <visual>
            <geometry>
                <box size="0.1 0.1 0.1"/>
            </geometry>
        </visual>

        <collision>
            <geometry>
                <box size="0.1 0.1 0.1"/>
            </geometry>
        </collision>
    </link>
    
    <link name="leg">
        <inertial>
            <mass value="2"/>
            <origin xyz="0 0 0.1" rpy="0 0 0" />
            <inertia ixx="0.008333" iyy="0.0070" izz="0.002" ixy="0" ixz="0" iyz="0"/>
        </inertial>

        <visual>
            <origin xyz="0 0 0.1" rpy="0 0 0" />
            <geometry>
                <box size="0.05 0.1 0.2"/>
            </geometry>
        </visual>

        <collision>
            <origin xyz="0 0 0.1" rpy="0 0 0" />
            <geometry>
                <box size="0.05 0.1 0.2"/>
            </geometry>
        </collision>
    </link>
    
    <link name="torso">
        <inertial>
            <mass value="2"/>
            <origin xyz="0 0 0.1" rpy="0 0 0" />
            <inertia ixx="0.021667" iyy="0.0070" izz="0.015417" ixy="0" ixz="0" iyz="0"/>
        </inertial>

        <visual>
            <origin xyz="0 0 0.1" rpy="0 0 0" />
            <geometry>
                <box size="0.05 0.3 0.2"/>
            </geometry>
        </visual>

        <collision>
            <origin xyz="0 0 0.1" rpy="0 0 0" />
            <geometry>
                <box size="0.05 0.3 0.2"/>
            </geometry>
        </collision>
    </link>
        
    <joint name="ankle" type="revolute">
        <origin xyz="-0.025 0.0 0.05" rpy="0 0 0"/>
        <parent link="foot"/>
        <child link="leg"/>
        <dynamics damping="0.1" friction="0.0"/>
        <limit effort="30" velocity="1.0" lower="-10.0" upper="10.0" />
        <axis xyz="0 1 0" />
    </joint>
    
    <joint name="hip" type="revolute">
        <origin xyz="0.0 0.0 0.2" rpy="0 0 0"/>
        <parent link="leg"/>
        <child link="torso"/>
        <dynamics damping="0.1" friction="0.0"/>
        <limit effort="30" velocity="1.0" lower="-10.0" upper="10.0" />
        <axis xyz="0 1 0" />
    </joint>

</robot>
